{
  "timestamp": 1754916947.9579377,
  "port_availability": {
    "5432": {
      "service": "PostgreSQL",
      "status": "closed",
      "accessible": false,
      "response_time_ms": null,
      "message": "PostgreSQL port 5432 is not accessible"
    },
    "6379": {
      "service": "Redis",
      "status": "closed",
      "accessible": false,
      "response_time_ms": null,
      "message": "Redis port 6379 is not accessible"
    },
    "7474": {
      "service": "Neo4j HTTP",
      "status": "closed",
      "accessible": false,
      "response_time_ms": null,
      "message": "Neo4j HTTP port 7474 is not accessible"
    },
    "7687": {
      "service": "Neo4j Bolt",
      "status": "closed",
      "accessible": false,
      "response_time_ms": null,
      "message": "Neo4j Bolt port 7687 is not accessible"
    },
    "8001": {
      "service": "ChromaDB",
      "status": "closed",
      "accessible": false,
      "response_time_ms": null,
      "message": "ChromaDB port 8001 is not accessible"
    }
  },
  "port_conflicts": [
    {
      "port": null,
      "services": [],
      "severity": "medium",
      "message": "Could not check for port conflicts: [Errno 2] No such file or directory: 'netstat'"
    }
  ],
  "network_connectivity": {
    "postgres": {
      "status": "not_accessible",
      "error": "Connection failed with code 111",
      "endpoint": "localhost:5432"
    },
    "redis": {
      "status": "not_accessible",
      "error": "Connection failed with code 111",
      "endpoint": "localhost:6379"
    },
    "neo4j_http": {
      "status": "error",
      "error": "HTTPConnectionPool(host='localhost', port=7474): Max retries exceeded with url: / (Caused by NewConnectionError('<urllib3.connection.HTTPConnection object at 0x7f086b1a0110>: Failed to establish a new connection: [Errno 111] Connection refused'))",
      "endpoint": "localhost:7474"
    },
    "neo4j_bolt": {
      "status": "not_accessible",
      "error": "Connection failed with code 111",
      "endpoint": "localhost:7687"
    },
    "chromadb": {
      "status": "error",
      "error": "HTTPConnectionPool(host='localhost', port=8001): Max retries exceeded with url: /api/v1/heartbeat (Caused by NewConnectionError('<urllib3.connection.HTTPConnection object at 0x7f086b13ef60>: Failed to establish a new connection: [Errno 111] Connection refused'))",
      "endpoint": "localhost:8001"
    }
  },
  "docker_networking": {
    "networks": [
      {
        "id": "b17a1413fe26",
        "name": "bridge",
        "driver": "bridge"
      },
      {
        "id": "02b0f9c2d3fc",
        "name": "host",
        "driver": "host"
      },
      {
        "id": "6799da15ef52",
        "name": "none",
        "driver": "null"
      },
      {
        "id": "321e2e63a581",
        "name": "sutazai-network",
        "driver": "bridge"
      }
    ],
    "network_count": 4,
    "container_connectivity": {
      "sutazai-postgres": {
        "ip": null,
        "status": "not_running",
        "network_accessible": false
      },
      "sutazai-redis": {
        "ip": null,
        "status": "not_running",
        "network_accessible": false
      },
      "sutazai-neo4j": {
        "ip": null,
        "status": "not_running",
        "network_accessible": false
      },
      "sutazai-chromadb": {
        "ip": null,
        "status": "not_running",
        "network_accessible": false
      }
    }
  },
  "overall_status": "failed"
}