#!/usr/bin/env python3.11
"""
Complete coverage tests for the supreme_ai module.
These tests are specifically designed to cover lines that aren't covered by existing tests.
"""

import asyncio
import pytest
from unittest.mock import MagicMock, patch, AsyncMock
from datetime import datetime

from core_system.orchestrator.models import (
    OrchestratorConfig, Agent, AgentStatus, Task, TaskStatus,
    SyncData, ServerConfig
)
from core_system.orchestrator.supreme_ai import SupremeAIOrchestrator
from core_system.orchestrator.exceptions import (
    OrchestratorError, AgentError, AgentNotFoundError, TaskError
)

@pytest.fixture
def config():
    """Create a test configuration."""
    return OrchestratorConfig(
        primary_server="primary",
        secondary_server="secondary",
        sync_interval=60,
        max_agents=10,
        task_timeout=300
    )

@pytest.fixture
def supreme_ai(config):
    """Create a SupremeAIOrchestrator instance for testing."""
    return SupremeAIOrchestrator(config=config)

@pytest.fixture
def agent_dict():
    """Create a test agent dictionary."""
    return {
        "id": "test-agent-1",
        "type": "test",
        "capabilities": ["capability1", "capability2"]
    }

@pytest.fixture
def task_dict():
    """Create a test task dictionary."""
    return {
        "id": "test-task-1",
        "type": "test",
        "parameters": {"param1": "value1"}
    }

class TestSupremeAICompleteCoverage:
    """Test class for complete coverage of SupremeAIOrchestrator."""
    
    @pytest.mark.asyncio
    async def test_start_exception(self, supreme_ai):
        """Test starting the orchestrator with an exception."""
        # Mock agent_manager.start to raise an exception
        supreme_ai.agent_manager.start = AsyncMock(side_effect=Exception("test exception"))
        
        # Call start
        with pytest.raises(OrchestratorError):
            await supreme_ai.start()
        
        # Verify
        supreme_ai.agent_manager.start.assert_called_once()
        assert not supreme_ai.is_running

    @pytest.mark.asyncio
    async def test_stop_exception(self, supreme_ai):
        """Test stopping the orchestrator with an exception."""
        # First start the orchestrator
        supreme_ai.is_running = True
        
        # Mock methods to raise exceptions
        supreme_ai.agent_manager.stop = AsyncMock(side_effect=Exception("test exception"))
        supreme_ai.task_queue.stop = AsyncMock()
        supreme_ai.sync_manager.stop = AsyncMock()
        
        # Call stop
        with pytest.raises(OrchestratorError):
            await supreme_ai.stop()
        
        # Verify that other methods were still called despite the exception
        supreme_ai.task_queue.stop.assert_called_once()
        supreme_ai.sync_manager.stop.assert_called_once()

    @pytest.mark.asyncio
    async def test_submit_task_exception(self, supreme_ai, task_dict):
        """Test submitting a task with an exception."""
        # Start the orchestrator
        supreme_ai.is_running = True
        
        # Mock task_queue.submit to raise an exception
        supreme_ai.task_queue.submit = AsyncMock(side_effect=Exception("test exception"))
        
        # Call submit_task
        with pytest.raises(TaskError):
            await supreme_ai.submit_task(task_dict)
        
        # Verify
        supreme_ai.task_queue.submit.assert_called_once()

    @pytest.mark.asyncio
    async def test_register_agent_exception(self, supreme_ai, agent_dict):
        """Test registering an agent with an exception."""
        # Start the orchestrator
        supreme_ai.is_running = True
        
        # Mock agent_manager.register_agent to raise an exception
        supreme_ai.agent_manager.register_agent = AsyncMock(side_effect=Exception("test exception"))
        
        # Call register_agent
        with pytest.raises(AgentError):
            await supreme_ai.register_agent(agent_dict)
        
        # Verify
        supreme_ai.agent_manager.register_agent.assert_called_once()

    @pytest.mark.asyncio
    async def test_get_agent_status_exception(self, supreme_ai):
        """Test getting agent status with an exception."""
        # Start the orchestrator
        supreme_ai.is_running = True
        
        # Mock agent_manager.get_agent_status to raise an exception
        supreme_ai.agent_manager.get_agent_status = AsyncMock(side_effect=Exception("test exception"))
        
        # Call get_agent_status
        with pytest.raises(AgentError):
            await supreme_ai.get_agent_status("test-agent")
        
        # Verify
        supreme_ai.agent_manager.get_agent_status.assert_called_once()

    @pytest.mark.asyncio
    async def test_list_agents_exception(self, supreme_ai):
        """Test listing agents with an exception."""
        # Start the orchestrator
        supreme_ai.is_running = True
        
        # Mock agent_manager.list_agents to raise an exception
        supreme_ai.agent_manager.list_agents = AsyncMock(side_effect=Exception("test exception"))
        
        # Call list_agents
        with pytest.raises(AgentError):
            await supreme_ai.list_agents()
        
        # Verify
        supreme_ai.agent_manager.list_agents.assert_called_once()

    @pytest.mark.asyncio
    async def test_start_agent_exception(self, supreme_ai):
        """Test starting an agent with an exception."""
        # Start the orchestrator
        supreme_ai.is_running = True
        
        # Mock agent_manager.start_agent to raise an exception
        supreme_ai.agent_manager.start_agent = AsyncMock(side_effect=Exception("test exception"))
        
        # Call start_agent
        with pytest.raises(AgentError):
            await supreme_ai.start_agent("test-agent")
        
        # Verify
        supreme_ai.agent_manager.start_agent.assert_called_once()

    @pytest.mark.asyncio
    async def test_stop_agent_exception(self, supreme_ai):
        """Test stopping an agent with an exception."""
        # Start the orchestrator
        supreme_ai.is_running = True
        
        # Mock agent_manager.stop_agent to raise an exception
        supreme_ai.agent_manager.stop_agent = AsyncMock(side_effect=Exception("test exception"))
        
        # Call stop_agent
        with pytest.raises(AgentError):
            await supreme_ai.stop_agent("test-agent")
        
        # Verify
        supreme_ai.agent_manager.stop_agent.assert_called_once()

    @pytest.mark.asyncio
    async def test_start_sync_exception(self, supreme_ai):
        """Test starting sync with an exception."""
        # Start the orchestrator
        supreme_ai.is_running = True
        
        # Mock sync_manager.start to raise an exception
        supreme_ai.sync_manager.start = AsyncMock(side_effect=Exception("test exception"))
        
        # Call start_sync
        with pytest.raises(OrchestratorError):
            await supreme_ai.start_sync()
        
        # Verify
        supreme_ai.sync_manager.start.assert_called_once()

    @pytest.mark.asyncio
    async def test_stop_sync_exception(self, supreme_ai):
        """Test stopping sync with an exception."""
        # Start the orchestrator
        supreme_ai.is_running = True
        
        # Mock sync_manager.stop to raise an exception
        supreme_ai.sync_manager.stop = AsyncMock(side_effect=Exception("test exception"))
        
        # Call stop_sync
        with pytest.raises(OrchestratorError):
            await supreme_ai.stop_sync()
        
        # Verify
        supreme_ai.sync_manager.stop.assert_called_once()

    @pytest.mark.asyncio
    async def test_deploy_exception(self, supreme_ai):
        """Test deploying with an exception."""
        # Start the orchestrator
        supreme_ai.is_running = True
        
        # Mock sync_manager.deploy to raise an exception
        supreme_ai.sync_manager.deploy = AsyncMock(side_effect=Exception("test exception"))
        
        # Call deploy
        with pytest.raises(OrchestratorError):
            await supreme_ai.deploy("target-server")
        
        # Verify
        supreme_ai.sync_manager.deploy.assert_called_once()

    @pytest.mark.asyncio
    async def test_rollback_exception(self, supreme_ai):
        """Test rolling back with an exception."""
        # Start the orchestrator
        supreme_ai.is_running = True
        
        # Mock sync_manager.rollback to raise an exception
        supreme_ai.sync_manager.rollback = AsyncMock(side_effect=Exception("test exception"))
        
        # Call rollback
        with pytest.raises(OrchestratorError):
            await supreme_ai.rollback("target-server")
        
        # Verify
        supreme_ai.sync_manager.rollback.assert_called_once()

    def test_get_status(self, supreme_ai):
        """Test getting status."""
        # Mock attributes
        supreme_ai.is_running = True
        supreme_ai.agent_manager.get_agent_count = MagicMock(return_value=5)
        
        # Call get_status
        result = supreme_ai.get_status()
        
        # Verify
        assert result["status"] == "running"
        assert result["agent_count"] == 5
        
    def test_process_tasks(self, supreme_ai):
        """Test processing tasks."""
        # Mock task_queue.process
        supreme_ai.task_queue.process = MagicMock()
        
        # Call process_tasks
        supreme_ai.process_tasks()
        
        # Verify
        supreme_ai.task_queue.process.assert_called_once()
        
    def test_sync(self, supreme_ai):
        """Test syncing."""
        # Mock sync_manager.sync
        supreme_ai.sync_manager.sync = MagicMock()
        
        # Call sync
        supreme_ai.sync()
        
        # Verify
        supreme_ai.sync_manager.sync.assert_called_once()
        
    def test_update_agent_heartbeat(self, supreme_ai):
        """Test updating agent heartbeat."""
        # Mock agent_manager.update_heartbeat
        supreme_ai.agent_manager.update_heartbeat = MagicMock()
        
        # Call update_agent_heartbeat
        supreme_ai.update_agent_heartbeat("test-agent")
        
        # Verify
        supreme_ai.agent_manager.update_heartbeat.assert_called_once_with("test-agent")
        
    @pytest.mark.asyncio
    async def test_get_next_task(self, supreme_ai):
        """Test getting the next task."""
        # Start the orchestrator
        supreme_ai.is_running = True
        
        # Mock task_queue.peek_next to return a task
        task = Task(id="test-task", type="test", parameters={})
        supreme_ai.task_queue.peek_next = AsyncMock(return_value=task)
        
        # Call get_next_task
        result = await supreme_ai.get_next_task()
        
        # Verify
        assert result["id"] == "test-task"
        
    @pytest.mark.asyncio
    async def test_get_next_task_no_task(self, supreme_ai):
        """Test getting the next task when there is no task."""
        # Start the orchestrator
        supreme_ai.is_running = True
        
        # Mock task_queue.peek_next to return None
        supreme_ai.task_queue.peek_next = AsyncMock(return_value=None)
        
        # Call get_next_task
        result = await supreme_ai.get_next_task()
        
        # Verify
        assert result == {}
        
    @pytest.mark.asyncio
    async def test_get_next_task_exception(self, supreme_ai):
        """Test getting the next task with an exception."""
        # Start the orchestrator
        supreme_ai.is_running = True
        
        # Mock task_queue.peek_next to raise an exception
        supreme_ai.task_queue.peek_next = AsyncMock(side_effect=Exception("test exception"))
        
        # Call get_next_task
        with pytest.raises(TaskError):
            await supreme_ai.get_next_task()
        
        # Verify
        supreme_ai.task_queue.peek_next.assert_called_once()
        
    @pytest.mark.asyncio
    async def test_get_task_queue_size(self, supreme_ai):
        """Test getting the task queue size."""
        # Start the orchestrator
        supreme_ai.is_running = True
        
        # Mock task_queue.size to return a value
        supreme_ai.task_queue.size = MagicMock(return_value=10)
        
        # Call get_task_queue_size
        result = await supreme_ai.get_task_queue_size()
        
        # Verify
        assert result == 10 