#!/usr/bin/env python3
"""
Targeted tests to achieve 100% coverage for supreme_ai.py
"""

import pytest
from unittest.mock import patch, MagicMock, AsyncMock
from core_system.orchestrator import supreme_ai
from core_system.orchestrator.exceptions import AgentNotFoundError, OrchestratorError
from core_system.orchestrator.models import OrchestratorConfig

@pytest.fixture
def config():
    """Fixture for OrchestratorConfig"""
    return OrchestratorConfig(
        primary_server="192.168.100.28",
        secondary_server="192.168.100.100",
        sync_interval=60,
        max_agents=10,
        task_timeout=3600,
    )

@pytest.fixture
def orchestrator(config):
    """Create a test instance of SupremeAIOrchestrator"""
    return supreme_ai.SupremeAIOrchestrator(config)

@pytest.mark.asyncio
async def test_start_with_exception(orchestrator):
    """Test start method with an exception being raised"""
    # Mock task_queue to raise an exception when start is called
    orchestrator.task_queue = AsyncMock()
    orchestrator.task_queue.start = AsyncMock(side_effect=Exception("Test exception"))

    # Mock the agent_manager and sync_manager
    orchestrator.agent_manager = AsyncMock()
    orchestrator.sync_manager = AsyncMock()

    try:
        # Call start, which should raise OrchestratorError
        await orchestrator.start()
        pytest.fail("Expected OrchestratorError but none was raised")
    except OrchestratorError:
        # This is the expected exception
        pass

    # Verify the is_running flag was set to False
    assert orchestrator.is_running is False

@pytest.mark.asyncio
async def test_stop_with_exception(orchestrator):
    """Test stop method with an exception being raised"""
    # Set the is_running flag
    orchestrator.is_running = True

    # Mock task_queue to raise an exception when stop is called
    orchestrator.task_queue = AsyncMock()
    orchestrator.task_queue.stop = AsyncMock(side_effect=Exception("Test exception"))

    # Set other components
    orchestrator.agent_manager = AsyncMock()
    orchestrator.sync_manager = AsyncMock()

    try:
        # Call stop, which should raise OrchestratorError
        await orchestrator.stop()
        pytest.fail("Expected OrchestratorError but none was raised")
    except OrchestratorError:
        # This is the expected exception
        pass

@pytest.mark.asyncio
async def test_submit_task_with_exception(orchestrator):
    """Test submit_task method with an exception being raised"""
    # Set the is_running flag
    orchestrator.is_running = True

    # Mock task_queue to raise an exception when put is called
    orchestrator.task_queue = AsyncMock()
    orchestrator.task_queue.put = AsyncMock(side_effect=Exception("Test exception"))

    # Call submit_task, which should handle the exception
    task = {"id": "task1", "type": "test"}
    try:
        await orchestrator.submit_task(task)
        pytest.fail("Expected OrchestratorError but none was raised")
    except OrchestratorError:
        # This is the expected exception
        pass

@pytest.mark.asyncio
async def test_register_agent_with_exception(orchestrator):
    """Test register_agent method with an exception being raised"""
    # Set the is_running flag
    orchestrator.is_running = True

    # Mock agent_manager to raise an exception when register_agent is called
    orchestrator.agent_manager = AsyncMock()
    orchestrator.agent_manager.register_agent = AsyncMock(side_effect=Exception("Test exception"))

    # Call register_agent, which should handle the exception
    agent = {"id": "agent1", "capabilities": ["test"]}
    try:
        await orchestrator.register_agent(agent)
        pytest.fail("Expected OrchestratorError but none was raised")
    except OrchestratorError:
        # This is the expected exception
        pass

@pytest.mark.asyncio
async def test_get_agent_status_with_exception(orchestrator):
    """Test get_agent_status method with an exception being raised"""
    # Mock agent_manager to raise an exception when get_agent_status is called
    orchestrator.agent_manager = AsyncMock()
    orchestrator.agent_manager.get_agent_status = AsyncMock(side_effect=Exception("Test exception"))

    # Call get_agent_status, which should handle the exception
    try:
        await orchestrator.get_agent_status("agent1")
        pytest.fail("Expected exception to be raised")
    except Exception:
        # This is the expected outcome
        pass

@pytest.mark.asyncio
async def test_list_agents_with_exception(orchestrator):
    """Test list_agents method with an exception being raised"""
    # Mock agent_manager to raise an exception when list_agents is called
    orchestrator.agent_manager = AsyncMock()
    orchestrator.agent_manager.list_agents = AsyncMock(side_effect=Exception("Test exception"))

    # Call list_agents, which should handle the exception
    try:
        await orchestrator.list_agents()
        pytest.fail("Expected exception to be raised")
    except Exception:
        # This is the expected outcome
        pass

@pytest.mark.asyncio
async def test_start_agent_with_exception(orchestrator):
    """Test start_agent method with an exception being raised"""
    # Mock agent_manager to raise an exception when start_agent is called
    orchestrator.agent_manager = AsyncMock()
    orchestrator.agent_manager.start_agent = AsyncMock(side_effect=Exception("Test exception"))

    # Call start_agent, which should handle the exception
    try:
        await orchestrator.start_agent("agent1")
        pytest.fail("Expected exception to be raised")
    except Exception:
        # This is the expected outcome
        pass

@pytest.mark.asyncio
async def test_stop_agent_with_exception(orchestrator):
    """Test stop_agent method with an exception being raised"""
    # Mock agent_manager to raise an exception when stop_agent is called
    orchestrator.agent_manager = AsyncMock()
    orchestrator.agent_manager.stop_agent = AsyncMock(side_effect=Exception("Test exception"))

    # Call stop_agent, which should handle the exception
    try:
        await orchestrator.stop_agent("agent1")
        pytest.fail("Expected exception to be raised")
    except Exception:
        # This is the expected outcome
        pass

@pytest.mark.asyncio
async def test_start_sync_with_exception(orchestrator):
    """Test start_sync method with an exception being raised"""
    # Mock sync_manager to raise an exception when start is called
    orchestrator.sync_manager = AsyncMock()
    orchestrator.sync_manager.start = AsyncMock(side_effect=Exception("Test exception"))

    # Call start_sync, which should handle the exception
    try:
        await orchestrator.start_sync()
        pytest.fail("Expected exception to be raised")
    except Exception:
        # This is the expected outcome
        pass

@pytest.mark.asyncio
async def test_stop_sync_with_exception(orchestrator):
    """Test stop_sync method with an exception being raised"""
    # Mock sync_manager to raise an exception when stop is called
    orchestrator.sync_manager = AsyncMock()
    orchestrator.sync_manager.stop = AsyncMock(side_effect=Exception("Test exception"))

    # Call stop_sync, which should handle the exception
    try:
        await orchestrator.stop_sync()
        pytest.fail("Expected exception to be raised")
    except Exception:
        # This is the expected outcome
        pass

@pytest.mark.asyncio
async def test_get_sync_status_with_exception(orchestrator):
    """Test get_sync_status method with an exception being raised"""
    # Mock sync_manager to raise an exception when get_status is called
    orchestrator.sync_manager = AsyncMock()
    orchestrator.sync_manager.get_status = AsyncMock(side_effect=Exception("Test exception"))

    # Call get_sync_status, which should handle the exception
    try:
        await orchestrator.get_sync_status()
        pytest.fail("Expected exception to be raised")
    except Exception:
        # This is the expected outcome
        pass

@pytest.mark.asyncio
async def test_process_next_task_with_exception(orchestrator):
    """Test process_next_task method with an exception being raised"""
    # Set the is_running flag
    orchestrator.is_running = True

    # Mock task_queue to raise an exception when get is called
    orchestrator.task_queue = AsyncMock()
    orchestrator.task_queue.get = AsyncMock(side_effect=Exception("Test exception"))

    # Call process_next_task, which should handle the exception
    try:
        await orchestrator.process_next_task()
        pytest.fail("Expected exception to be raised")
    except Exception:
        # This is the expected outcome
        pass

@pytest.mark.asyncio
async def test_get_task_queue_size_with_exception(orchestrator):
    """Test get_task_queue_size method with an exception being raised"""
    # Mock task_queue to raise an exception when size is accessed
    orchestrator.task_queue = MagicMock()

    # Create a property mock for size that raises an exception
    mock_property = property(lambda self: (_ for _ in ()).throw(Exception("Test exception")))
    type(orchestrator.task_queue).size = mock_property

    # Call get_task_queue_size, which should handle the exception
    try:
        await orchestrator.get_task_queue_size()
        pytest.fail("Expected exception to be raised")
    except Exception:
        # This is the expected outcome
        pass

@pytest.mark.asyncio
async def test_create_task_with_exception(orchestrator):
    """Test create_task method with an exception being raised"""
    # Call create_task with invalid parameters, which should handle the exception
    try:
        # This should raise an exception since 'id' and 'type' are required
        await orchestrator.create_task({})
        pytest.fail("Expected exception to be raised")
    except Exception:
        # This is the expected outcome
        pass
